[2023-12-17T11:51:11.882+0000] {logging_mixin.py:154} INFO - Changing /opt/***/logs/dag_id=air_quality/run_id=manual__2023-12-17T11:44:49.387829+00:00/task_id=Insert_Data permission to 509
[2023-12-17T11:51:11.883+0000] {logging_mixin.py:154} INFO - Failed to change /opt/***/logs/dag_id=air_quality/run_id=manual__2023-12-17T11:44:49.387829+00:00/task_id=Insert_Data permission to 509: [Errno 1] Operation not permitted: '/opt/***/logs/dag_id=air_quality/run_id=manual__2023-12-17T11:44:49.387829+00:00/task_id=Insert_Data'
[2023-12-17T11:51:11.918+0000] {logging_mixin.py:154} INFO - Changing /opt/***/logs/dag_id=air_quality/run_id=manual__2023-12-17T11:44:49.387829+00:00/task_id=Insert_Data permission to 509
[2023-12-17T11:51:11.919+0000] {logging_mixin.py:154} INFO - Failed to change /opt/***/logs/dag_id=air_quality/run_id=manual__2023-12-17T11:44:49.387829+00:00/task_id=Insert_Data permission to 509: [Errno 1] Operation not permitted: '/opt/***/logs/dag_id=air_quality/run_id=manual__2023-12-17T11:44:49.387829+00:00/task_id=Insert_Data'
[2023-12-17T11:51:11.960+0000] {taskinstance.py:1159} INFO - Dependencies all met for dep_context=non-requeueable deps ti=<TaskInstance: air_quality.Insert_Data manual__2023-12-17T11:44:49.387829+00:00 [queued]>
[2023-12-17T11:51:11.973+0000] {taskinstance.py:1159} INFO - Dependencies all met for dep_context=requeueable deps ti=<TaskInstance: air_quality.Insert_Data manual__2023-12-17T11:44:49.387829+00:00 [queued]>
[2023-12-17T11:51:11.974+0000] {taskinstance.py:1361} INFO - Starting attempt 2 of 2
[2023-12-17T11:51:11.989+0000] {taskinstance.py:1382} INFO - Executing <Task(PythonOperator): Insert_Data> on 2023-12-17 11:44:49.387829+00:00
[2023-12-17T11:51:11.993+0000] {standard_task_runner.py:57} INFO - Started process 3159 to run task
[2023-12-17T11:51:11.996+0000] {standard_task_runner.py:84} INFO - Running: ['***', 'tasks', 'run', 'air_quality', 'Insert_Data', 'manual__2023-12-17T11:44:49.387829+00:00', '--job-id', '463', '--raw', '--subdir', 'DAGS_FOLDER/airQuality.py', '--cfg-path', '/tmp/tmp7n_1pn5v']
[2023-12-17T11:51:11.997+0000] {standard_task_runner.py:85} INFO - Job 463: Subtask Insert_Data
[2023-12-17T11:51:12.053+0000] {logging_mixin.py:154} INFO - Changing /opt/***/logs/dag_id=air_quality/run_id=manual__2023-12-17T11:44:49.387829+00:00/task_id=Insert_Data permission to 509
[2023-12-17T11:51:12.054+0000] {logging_mixin.py:154} INFO - Failed to change /opt/***/logs/dag_id=air_quality/run_id=manual__2023-12-17T11:44:49.387829+00:00/task_id=Insert_Data permission to 509: [Errno 1] Operation not permitted: '/opt/***/logs/dag_id=air_quality/run_id=manual__2023-12-17T11:44:49.387829+00:00/task_id=Insert_Data'
[2023-12-17T11:51:12.057+0000] {task_command.py:416} INFO - Running <TaskInstance: air_quality.Insert_Data manual__2023-12-17T11:44:49.387829+00:00 [running]> on host 1a58977f5573
[2023-12-17T11:51:12.156+0000] {taskinstance.py:1662} INFO - Exporting env vars: AIRFLOW_CTX_DAG_OWNER='ghifari' AIRFLOW_CTX_DAG_ID='air_quality' AIRFLOW_CTX_TASK_ID='Insert_Data' AIRFLOW_CTX_EXECUTION_DATE='2023-12-17T11:44:49.387829+00:00' AIRFLOW_CTX_TRY_NUMBER='2' AIRFLOW_CTX_DAG_RUN_ID='manual__2023-12-17T11:44:49.387829+00:00'
[2023-12-17T11:51:12.684+0000] {logging_mixin.py:154} INFO - city           object
country        object
unit           object
last_value    float64
lat           float64
lng           float64
dtype: object
[2023-12-17T11:51:12.695+0000] {base.py:73} INFO - Using connection ID 'neonServerDB-Postgres' for task execution.
[2023-12-17T11:51:14.580+0000] {taskinstance.py:1937} ERROR - Task failed with exception
Traceback (most recent call last):
  File "/home/airflow/.local/lib/python3.8/site-packages/airflow/operators/python.py", line 192, in execute
    return_value = self.execute_callable()
  File "/home/airflow/.local/lib/python3.8/site-packages/airflow/operators/python.py", line 209, in execute_callable
    return self.python_callable(*self.op_args, **self.op_kwargs)
  File "/opt/airflow/dags/airQuality.py", line 195, in insertValues
    cursor.execute(insertVal)
psycopg2.errors.UndefinedTable: relation "air_quality" does not exist
LINE 2:         INSERT INTO air_quality (city, country, unit, last_v...
                            ^

[2023-12-17T11:51:14.658+0000] {taskinstance.py:211} INFO - Setting task Error_Response to SKIPPED due to dag's `fail_stop` setting.
[2023-12-17T11:51:14.661+0000] {taskinstance.py:1400} INFO - Marking task as FAILED. dag_id=air_quality, task_id=Insert_Data, execution_date=20231217T114449, start_date=20231217T115111, end_date=20231217T115114
[2023-12-17T11:51:14.712+0000] {standard_task_runner.py:104} ERROR - Failed to execute job 463 for task Insert_Data (relation "air_quality" does not exist
LINE 2:         INSERT INTO air_quality (city, country, unit, last_v...
                            ^
; 3159)
[2023-12-17T11:51:14.784+0000] {local_task_job_runner.py:228} INFO - Task exited with return code 1
[2023-12-17T11:51:14.822+0000] {taskinstance.py:2778} INFO - 0 downstream tasks scheduled from follow-on schedule check
