[2023-12-15T18:20:01.494+0000] {logging_mixin.py:154} INFO - Changing /opt/***/logs/dag_id=air_quality/run_id=manual__2023-12-15T18:20:00.031743+00:00/task_id=Insert_Data permission to 509
[2023-12-15T18:20:01.497+0000] {logging_mixin.py:154} INFO - Failed to change /opt/***/logs/dag_id=air_quality/run_id=manual__2023-12-15T18:20:00.031743+00:00/task_id=Insert_Data permission to 509: [Errno 1] Operation not permitted: '/opt/***/logs/dag_id=air_quality/run_id=manual__2023-12-15T18:20:00.031743+00:00/task_id=Insert_Data'
[2023-12-15T18:20:01.557+0000] {logging_mixin.py:154} INFO - Changing /opt/***/logs/dag_id=air_quality/run_id=manual__2023-12-15T18:20:00.031743+00:00/task_id=Insert_Data permission to 509
[2023-12-15T18:20:01.559+0000] {logging_mixin.py:154} INFO - Failed to change /opt/***/logs/dag_id=air_quality/run_id=manual__2023-12-15T18:20:00.031743+00:00/task_id=Insert_Data permission to 509: [Errno 1] Operation not permitted: '/opt/***/logs/dag_id=air_quality/run_id=manual__2023-12-15T18:20:00.031743+00:00/task_id=Insert_Data'
[2023-12-15T18:20:01.624+0000] {taskinstance.py:1159} INFO - Dependencies all met for dep_context=non-requeueable deps ti=<TaskInstance: air_quality.Insert_Data manual__2023-12-15T18:20:00.031743+00:00 [queued]>
[2023-12-15T18:20:01.646+0000] {taskinstance.py:1159} INFO - Dependencies all met for dep_context=requeueable deps ti=<TaskInstance: air_quality.Insert_Data manual__2023-12-15T18:20:00.031743+00:00 [queued]>
[2023-12-15T18:20:01.647+0000] {taskinstance.py:1361} INFO - Starting attempt 1 of 2
[2023-12-15T18:20:01.673+0000] {taskinstance.py:1382} INFO - Executing <Task(PythonOperator): Insert_Data> on 2023-12-15 18:20:00.031743+00:00
[2023-12-15T18:20:01.680+0000] {standard_task_runner.py:57} INFO - Started process 1895 to run task
[2023-12-15T18:20:01.686+0000] {standard_task_runner.py:84} INFO - Running: ['***', 'tasks', 'run', 'air_quality', 'Insert_Data', 'manual__2023-12-15T18:20:00.031743+00:00', '--job-id', '93', '--raw', '--subdir', 'DAGS_FOLDER/airQuality.py', '--cfg-path', '/tmp/tmp53gl3177']
[2023-12-15T18:20:01.689+0000] {standard_task_runner.py:85} INFO - Job 93: Subtask Insert_Data
[2023-12-15T18:20:01.782+0000] {logging_mixin.py:154} INFO - Changing /opt/***/logs/dag_id=air_quality/run_id=manual__2023-12-15T18:20:00.031743+00:00/task_id=Insert_Data permission to 509
[2023-12-15T18:20:01.784+0000] {logging_mixin.py:154} INFO - Failed to change /opt/***/logs/dag_id=air_quality/run_id=manual__2023-12-15T18:20:00.031743+00:00/task_id=Insert_Data permission to 509: [Errno 1] Operation not permitted: '/opt/***/logs/dag_id=air_quality/run_id=manual__2023-12-15T18:20:00.031743+00:00/task_id=Insert_Data'
[2023-12-15T18:20:01.788+0000] {task_command.py:416} INFO - Running <TaskInstance: air_quality.Insert_Data manual__2023-12-15T18:20:00.031743+00:00 [running]> on host d739bc9bef06
[2023-12-15T18:20:01.952+0000] {taskinstance.py:1662} INFO - Exporting env vars: AIRFLOW_CTX_DAG_OWNER='ghifari' AIRFLOW_CTX_DAG_ID='air_quality' AIRFLOW_CTX_TASK_ID='Insert_Data' AIRFLOW_CTX_EXECUTION_DATE='2023-12-15T18:20:00.031743+00:00' AIRFLOW_CTX_TRY_NUMBER='1' AIRFLOW_CTX_DAG_RUN_ID='manual__2023-12-15T18:20:00.031743+00:00'
[2023-12-15T18:20:01.979+0000] {taskinstance.py:1937} ERROR - Task failed with exception
Traceback (most recent call last):
  File "/home/airflow/.local/lib/python3.8/site-packages/airflow/operators/python.py", line 192, in execute
    return_value = self.execute_callable()
  File "/home/airflow/.local/lib/python3.8/site-packages/airflow/operators/python.py", line 209, in execute_callable
    return self.python_callable(*self.op_args, **self.op_kwargs)
  File "/opt/airflow/dags/airQuality.py", line 141, in insertValues
    result = resultTransformation.to_dict(orient='records')
AttributeError: 'NoneType' object has no attribute 'to_dict'
[2023-12-15T18:20:02.001+0000] {taskinstance.py:1400} INFO - Marking task as UP_FOR_RETRY. dag_id=air_quality, task_id=Insert_Data, execution_date=20231215T182000, start_date=20231215T182001, end_date=20231215T182002
[2023-12-15T18:20:02.027+0000] {standard_task_runner.py:104} ERROR - Failed to execute job 93 for task Insert_Data ('NoneType' object has no attribute 'to_dict'; 1895)
[2023-12-15T18:20:02.063+0000] {local_task_job_runner.py:228} INFO - Task exited with return code 1
[2023-12-15T18:20:02.113+0000] {taskinstance.py:2778} INFO - 0 downstream tasks scheduled from follow-on schedule check
